Workbook

Sheet 01_Organigrama_y_Roles
B4: PLANIFICACIÓN Y CONTROL DE OBRAS · ES3
B6: SEDE SOCIAL EL BOSQUE
B11: Programa, costos y control de ejecución
B14: PLAZO PLANIFICADO | D14: 150 días corridos
B15: INICIO PROGRAMADO | D15: 02 de noviembre de 2026
B16: ALCANCE | D16: Construcción de sede social
B18: DOCENTE | D18: Francisca Pizarro Oliveros
B20: INTEGRANTES · GRUPO 4
B21: Mario Pinto
B22: Gerardo Pavez
B23: Tomas Correa
B24: Eliasin Roman
A31: PASO 1 · ORGANIGRAMA DE PROYECTO · ES3 IND. 1
B132: MATRIZ DE ROLES Y RESPONSABILIDADES · ES3 IND. 1
B135: ES3 - IND. 1 | MATRIZ DE ROLES Y RESPONSABILIDADES
B137: Construcción Sede Social El Bosque | Andacollo | Matriz concordante con el organigrama
B138: Los KPI indicados son indicadores de seguimiento de gestión; deben ajustarse al contrato, programa y procedimientos aprobados.
B140: Cargo | C140: Dependencia directa | D140: Funciones principales | E140: Entregables / KPI bajo su responsabilidad
B141: Mandante / Propietario | C141: Ilustre Municipalidad de Andacollo | D141: Define el objetivo y necesidades del proyecto; dispone del contrato; valida decisiones que afecten alcance, plazo o costo; participa en definiciones formales. | E141: Contrato y decisiones formales; aprobaciones del mandante; cumplimiento del objetivo; trazabilidad de cambios autorizados.
B142: Inspección Técnica de Obra (ITO) | C142: Mandante / Municipalidad (Control externo) | D142: Inspecciona ejecución, avance y calidad; revisa materiales y partidas; formula observaciones; resuelve consultas por encargo del municipio; otorga V°B° antes de continuar partidas. | E142: Actas y registros de inspección; % partidas con V°B°; observaciones abiertas/cerradas; tiempos de respuesta; recepción de partidas.
B143: Dirección de Obra / Contratista | C143: Mandante e ITO (Relación contractual) | D143: Lidera la ejecución integral; asegura cumplimiento de EE.TT., planos y normativa; dispone recursos; coordina proyectistas, ITO y equipos; responde por discrepancias y resultados. | E143: Plan de ejecución; cumplimiento de hitos; desviación de costo/plazo; respuestas a discrepancias; recepción provisoria y cierre contractual.
B144: Administrador de Obra | C144: Dirección de Obra / Contratista | D144: Administra contrato, programa, costos, adquisiciones y coordinación general; mantiene relación operativa con ITO; consolida reportes y decisiones de obra. | E144: Informe semanal; avance físico-financiero; control de cambios; curva S; compromisos con ITO; RFI críticos; forecast de costo/plazo.
B145: Jefe de Terreno | C145: Administrador de Obra | D145: Planifica producción diaria y semanal; coordina frentes, cuadrillas, equipos, materiales y restricciones; verifica secuencia y liberación de actividades. | E145: Lookahead 3-6 semanas; partes diarios; % cumplimiento plan semanal; productividad; restricciones levantadas; avance por frente.
B146: Jefe Oficina Técnica / Coordinador BIM | C146: Administrador de Obra | D146: Coordina arquitectura, estructura y especialidades; administra planos y revisiones; gestiona RFI, submittals, interferencias, información BIM y antecedentes conforme a obra. | E146: Matriz RFI; planos vigentes; reportes de interferencias; submittals aprobados; control de revisiones; modelo/planos as-built; % documentos en plazo.
B147: Encargado de Calidad PAC | C147: Administrador de Obra (Funcional con ITO) | D147: Implementa PAC/ITP; controla inspecciones y ensayos; verifica certificados, trazabilidad y criterios de aceptación; gestiona no conformidades y liberación de partidas. | E147: PAC e ITP; checklists; protocolos; certificados; registros de trazabilidad; % primera pasada; NCR abiertas/cerradas; V°B° de calidad.
B148: Encargado SSOMA | C148: Administrador de Obra | D148: Gestiona seguridad, salud ocupacional y medio ambiente; aplica Ley 16.744, D.S. 594 y controles preventivos; coordina inducciones, permisos, EPP, señalización y emergencias. | E148: Matriz de riesgos; inducciones; AST/charlas; inspecciones; permisos de trabajo; tasa de incidentes; cumplimiento de capacitaciones; acciones correctivas cerradas.
B149: Bodeguero | C149: Jefe de Terreno / Administrador de Obra | D149: Recibe y verifica materiales; controla almacenamiento, inventario, orden, protección y entrega; mantiene trazabilidad y comunica quiebres o daños. | E149: Kardex / inventario; recepción conforme; exactitud de stock; entregas oportunas; materiales protegidos; pérdidas y daños controlados.
B150: Capataz Obra Gruesa | C150: Jefe de Terreno | D150: Conduce cuadrillas y ejecuta fundaciones, radier, estructura y demás partidas de obra gruesa conforme a planos, secuencia, calidad y seguridad. | E150: Avance por frente; checklists; productividad; horas-hombre; controles previos; retrabajos; observaciones PAC/SSOMA cerradas.
B151: Capataz Terminaciones | C151: Jefe de Terreno | D151: Conduce revestimientos, pavimentos, pinturas, cielos, artefactos, remates y limpieza; coordina liberación de recintos con calidad y especialidades. | E151: Avance de terminaciones; punch list; % recepción primera vez; retrabajos; recintos liberados; observaciones de ITO cerradas.
B152: Personal de terreno y subcontratos | C152: Jefe de Terreno / Capataz correspondiente | D152: Ejecutan las actividades asignadas conforme a instrucciones, planos vigentes, procedimientos de trabajo, controles de calidad y medidas SSOMA. | E152: Producción diaria; asistencia y rendimiento; cumplimiento de procedimientos; incidentes; no conformidades; avances y registros de ejecución.
B154: Base documental: 7-EE.TT_SEDE_EL_BOSQUE.pdf - Especificaciones Técnicas “Construcción Sede Social El Bosque, Comuna Andacollo”, agosto 2025. Apartados considerados: 0.1 Generalidades; 0.2 Productos y materiales; 0.3 Obligaciones del contratista; 0.4 Ubicación; 0.5 Propietario; 0.6 Marco normativo; A.1 Instalación de faenas; B.1 Obra gruesa; B.2 Terminaciones.

Sheet 02_Rendimientos
A1: PASO 2 · RENDIMIENTOS POR CUADRILLA Y TIEMPOS · ES3 IND. 2
A2: Construcción Sede Social El Bosque | Andacollo | Plazo contractual mínimo: 150 días corridos
A3: La duración planificada utiliza frentes de trabajo paralelos. La ponderación orienta el programa, pero la secuencia CPM determina las fechas de inicio y término.
A5: Ítem | B5: Macro-etapa | C5: Partida | D5: Cantidad referencial | E5: Unidad | F5: Cuadrilla tipo | G5: Rendimiento diario | H5: N° cuadrillas | I5: Duración base | J5: Ponderación objetivo | K5: Duración planificada (días)
A6: 1 | B6: Instalación de faenas | C6: Instalación de faenas y cierre perimetral | D6: 1 | E6: lote | F6: 1 Maestro + 2 Ayudantes | G6: 1 | H6: 1 | I6: =D6/(G6*H6) -> 1 | J6: 0.08 | K6: 6
A7: 2 | B7: Instalación de faenas | C7: Replanteo y nivelación del área de trabajo | D7: 180 | E7: m2 | F7: 1 Topógrafo + 1 Ayudante | G7: 180 | H7: 1 | I7: =D7/(G7*H7) -> 1 | J7: 0.08 | K7: 5
A8: 3 | B8: Instalación de faenas | C8: Servicios provisorios y habilitación de instalaciones | D8: 1 | E8: lote | F8: 1 Maestro + 1 Ayudante | G8: 0.5 | H8: 1 | I8: =D8/(G8*H8) -> 2 | J8: 0.08 | K8: 10
A9: 4 | B9: Obra Gruesa | C9: Excavación y retiro de material | D9: 45 | E9: m3 | F9: 1 Operador + 2 Ayudantes | G9: 15 | H9: 1 | I9: =D9/(G9*H9) -> 3 | J9: 0.38 | K9: 11
A10: 5 | B10: Obra Gruesa | C10: Relleno, humectación y compactación | D10: 35 | E10: m3 | F10: 1 Maestro + 2 Ayudantes | G10: 12 | H10: 1 | I10: =D10/(G10*H10) -> 2.9166667 | J10: 0.38 | K10: 9
A11: 6 | B11: Obra Gruesa | C11: Emplantillado de hormigón | D11: 12 | E11: m3 | F11: 1 Maestro + 2 Ayudantes | G11: 4 | H11: 1 | I11: =D11/(G11*H11) -> 3 | J11: 0.38 | K11: 5
A12: 7 | B12: Obra Gruesa | C12: Fundaciones de hormigón armado | D12: 28 | E12: m3 | F12: 1 Maestro + 3 Ayudantes | G12: 7 | H12: 1 | I12: =D12/(G12*H12) -> 4 | J12: 0.38 | K12: 13
A13: 8 | B13: Obra Gruesa | C13: Radier y losas de hormigón | D13: 95 | E13: m2 | F13: 1 Maestro + 3 Ayudantes | G13: 28 | H13: 1 | I13: =D13/(G13*H13) -> 3.3928571 | J13: 0.38 | K13: 12
A14: 9 | B14: Obra Gruesa | C14: Estructura metálica y viga reticulada | D14: 2800 | E14: kg | F14: 1 Soldador + 2 Ayudantes | G14: 350 | H14: 1 | I14: =D14/(G14*H14) -> 8 | J14: 0.38 | K14: 20
A15: 10 | B15: Obra Gruesa | C15: Cubierta y hojalatería | D15: 190 | E15: m2 | F15: 1 Maestro + 2 Ayudantes | G15: 45 | H15: 1 | I15: =D15/(G15*H15) -> 4.2222222 | J15: 0.38 | K15: 12
A16: 11 | B16: Obra Gruesa | C16: Muros y tabiques Metalcon | D16: 360 | E16: m2 | F16: 1 Maestro + 2 Ayudantes | G16: 45 | H16: 2 | I16: =D16/(G16*H16) -> 4 | J16: 0.38 | K16: 18
A17: 12 | B17: Instalaciones | C17: Instalación eléctrica interior | D17: 1 | E17: lote | F17: 1 Técnico Eléctrico + 1 Ayudante | G17: 0.25 | H17: 1 | I17: =D17/(G17*H17) -> 4 | J17: 0.22 | K17: 14
... A27: 22 | B27: Terminaciones | C27: Limpieza, remates y entrega | D27: 1 | E27: lote | F27: 1 Maestro + 2 Ayudantes | G27: 0.5 | H27: 1 | I27: =D27/(G27*H27) -> 2 | J27: 0.32 | K27: 7
A30: CONTROL DE PLAZO
A31: Macro-etapa | B31: Ponderación objetivo | C31: Días de referencia | D31: Criterio de programación | F31: Criterio adoptado: el programa determinístico queda en 150 días corridos, cumpliendo el mínimo contractual de 150 días. Las tareas C, H, K, M, N, O, P, S y U se organizan como ramas paralelas o convergentes para representar una obra ejecutable con varios frentes. Las cantidades y rendimientos son de planificación y deben validarse contra planos, presupuesto, EE.TT. y recursos reales.
A32: Instalación de faenas | B32: =J6 -> 0.08 | C32: =B32*'02_Rendimientos'!$B$80 -> 12 | D32: Habilitación inicial y logística
A33: Obra Gruesa | B33: =J9 -> 0.38 | C33: =B33*'02_Rendimientos'!$B$80 -> 57 | D33: Estructura, hormigones, muros y cubierta
A34: Instalaciones | B34: =J17 -> 0.22 | C34: =B34*'02_Rendimientos'!$B$80 -> 33 | D34: Redes eléctricas, sanitarias, pruebas y conexiones
A35: Terminaciones | B35: =J22 -> 0.32 | C35: =B35*'02_Rendimientos'!$B$80 -> 48 | D35: Revestimientos, pavimentos, pintura y cierre
A36: Las ponderaciones son las adoptadas en esta planificación, no una transcripción acreditada de los porcentajes de clase. Los días de referencia suman 150; las etapas se superponen en CPM, por eso no se suman sus duraciones de ejecución.
A39: Duración base: jornadas productivas según cantidad y cuadrilla. Duración planificada: días corridos con esperas y coordinación. La cubicación contractual de las 140 partidas figura en el Paso 6.
A42: Act. | B42: Paquete del programa | C42: Jornadas base | D42: Días corridos | E42: Días a 5/7 | F42: Diferencia no productiva | G42: Interpretación
A43: A | B43: =C6 -> Instalación de faenas y cierre perimetral | C43: =I6 -> 1 | D43: =K6 -> 6 | E43: =D43*5/7 -> 4.2857143 | F43: =E43-C43 -> 3.2857143 | G43: Esperas y coordinación previstas. Validar en terreno.
A44: B | B44: =C7 -> Replanteo y nivelación del área de trabajo | C44: =I7 -> 1 | D44: =K7 -> 5 | E44: =D44*5/7 -> 3.5714286 | F44: =E44-C44 -> 2.5714286 | G44: Esperas y coordinación previstas. Validar en terreno.
A45: C | B45: =C8 -> Servicios provisorios y habilitación de instalaciones | C45: =I8 -> 2 | D45: =K8 -> 10 | E45: =D45*5/7 -> 7.1428571 | F45: =E45-C45 -> 5.1428571 | G45: Esperas y coordinación previstas. Validar en terreno.
A46: D | B46: =C9 -> Excavación y retiro de material | C46: =I9 -> 3 | D46: =K9 -> 11 | E46: =D46*5/7 -> 7.8571429 | F46: =E46-C46 -> 4.8571429 | G46: Esperas y coordinación previstas. Validar en terreno.
A47: E | B47: =C10 -> Relleno, humectación y compactación | C47: =I10 -> 2.9166667 | D47: =K10 -> 9 | E47: =D47*5/7 -> 6.4285714 | F47: =E47-C47 -> 3.5119048 | G47: Esperas y coordinación previstas. Validar en terreno.
A48: F | B48: =C11 -> Emplantillado de hormigón | C48: =I11 -> 3 | D48: =K11 -> 5 | E48: =D48*5/7 -> 3.5714286 | F48: =E48-C48 -> 0.57142857 | G48: Esperas y coordinación previstas. Validar en terreno.
A49: G | B49: =C12 -> Fundaciones de hormigón armado | C49: =I12 -> 4 | D49: =K12 -> 13 | E49: =D49*5/7 -> 9.2857143 | F49: =E49-C49 -> 5.2857143 | G49: Esperas y coordinación previstas. Validar en terreno.
A50: H | B50: =C13 -> Radier y losas de hormigón | C50: =I13 -> 3.3928571 | D50: =K13 -> 12 | E50: =D50*5/7 -> 8.5714286 | F50: =E50-C50 -> 5.1785714 | G50: Esperas y coordinación previstas. Validar en terreno.
A51: I | B51: =C14 -> Estructura metálica y viga reticulada | C51: =I14 -> 8 | D51: =K14 -> 20 | E51: =D51*5/7 -> 14.285714 | F51: =E51-C51 -> 6.2857143 | G51: Esperas y coordinación previstas. Validar en terreno.
A52: J | B52: =C15 -> Cubierta y hojalatería | C52: =I15 -> 4.2222222 | D52: =K15 -> 12 | E52: =D52*5/7 -> 8.5714286 | F52: =E52-C52 -> 4.3492063 | G52: Esperas y coordinación previstas. Validar en terreno.
A53: K | B53: =C16 -> Muros y tabiques Metalcon | C53: =I16 -> 4 | D53: =K16 -> 18 | E53: =D53*5/7 -> 12.857143 | F53: =E53-C53 -> 8.8571429 | G53: Esperas y coordinación previstas. Validar en terreno.
A54: L | B54: =C17 -> Instalación eléctrica interior | C54: =I17 -> 4 | D54: =K17 -> 14 | E54: =D54*5/7 -> 10 | F54: =E54-C54 -> 6 | G54: Esperas y coordinación previstas. Validar en terreno.
... A64: V | B64: =C27 -> Limpieza, remates y entrega | C64: =I27 -> 2 | D64: =K27 -> 7 | E64: =D64*5/7 -> 5 | F64: =E64-C64 -> 3 | G64: Esperas y coordinación previstas. Validar en terreno.
A72: PARÁMETROS Y SUPUESTOS DE CÁLCULO · ANEXO DEL PASO 2
...

Sheet 03_CPM_Obra_Gruesa
A2: CPM DE OBRA GRUESA - ES3 IND. 3
A3: CPM sectorial: 8 paquetes de programación asociados a 26 partidas presupuestarias de obra gruesa. La correspondencia por partida se presenta desde la fila 103.
A5: Red sectorial autónoma: día 0 local, 70.00 días. Entradas externas D depende de B se conservan en la red total, no en esta subred. No sumar su duración al plazo total.
A7: Lectura: arriba IT (inicio temprano) / FT (término temprano); abajo ITa (inicio tardío) / FTa (término tardío). Rojo: ruta crítica. Azul: actividades con holgura.
A40: TABLA SECTORIAL - RUTA CRÍTICA D → E → F → G → I → J
A41: Nodo | B41: EDT | C41: Partida / paquete | D41: Predecesoras locales | E41: Duración (d) | F41: IT | G41: FT | H41: ITa | I41: FTa | J41: HT | K41: HL | L41: Crítica
A42: ='03_CPM_Obra_Gruesa'!A148 -> D | B42: ='03_CPM_Obra_Gruesa'!B148 -> 2.1 | C42: ='03_CPM_Obra_Gruesa'!D148 -> Excavación y retiro de material | D42: — | E42: ='03_CPM_Obra_Gruesa'!E148 -> 11 | F42: =0 -> 0 | G42: =F42+E42 -> 11 | H42: =I42-E42 -> 0 | I42: =MIN(H43) -> 11 | J42: =H42-F42 -> 0 | K42: =MIN(F43)-G42 -> 0 | L42: =IF(ABS(J42)<0.0001,"SÍ","NO") -> SÍ
A43: ='03_CPM_Obra_Gruesa'!A149 -> E | B43: ='03_CPM_Obra_Gruesa'!B149 -> 2.2 | C43: ='03_CPM_Obra_Gruesa'!D149 -> Relleno, humectación y compactación | D43: D | E43: ='03_CPM_Obra_Gruesa'!E149 -> 9 | F43: =MAX(G42) -> 11 | G43: =F43+E43 -> 20 | H43: =I43-E43 -> 11 | I43: =MIN(H44) -> 20 | J43: =H43-F43 -> 0 | K43: =MIN(F44)-G43 -> 0 | L43: =IF(ABS(J43)<0.0001,"SÍ","NO") -> SÍ
A44: ='03_CPM_Obra_Gruesa'!A150 -> F | B44: ='03_CPM_Obra_Gruesa'!B150 -> 2.3 | C44: ='03_CPM_Obra_Gruesa'!D150 -> Emplantillado de hormigón | D44: E | E44: ='03_CPM_Obra_Gruesa'!E150 -> 5 | F44: =MAX(G43) -> 20 | G44: =F44+E44 -> 25 | H44: =I44-E44 -> 20 | I44: =MIN(H45) -> 25 | J44: =H44-F44 -> 0 | K44: =MIN(F45)-G44 -> 0 | L44: =IF(ABS(J44)<0.0001,"SÍ","NO") -> SÍ
A45: ='03_CPM_Obra_Gruesa'!A151 -> G | B45: ='03_CPM_Obra_Gruesa'!B151 -> 2.4 | C45: ='03_CPM_Obra_Gruesa'!D151 -> Fundaciones de hormigón armado | D45: F | E45: ='03_CPM_Obra_Gruesa'!E151 -> 13 | F45: =MAX(G44) -> 25 | G45: =F45+E45 -> 38 | H45: =I45-E45 -> 25 | I45: =MIN(H46,H47,H49) -> 38 | J45: =H45-F45 -> 0 | K45: =MIN(F46,F47,F49)-G45 -> 0 | L45: =IF(ABS(J45)<0.0001,"SÍ","NO") -> SÍ
A46: ='03_CPM_Obra_Gruesa'!A152 -> H | B46: ='03_CPM_Obra_Gruesa'!B152 -> 2.5 | C46: ='03_CPM_Obra_Gruesa'!D152 -> Radier y losas de hormigón | D46: G | E46: ='03_CPM_Obra_Gruesa'!E152 -> 12 | F46: =MAX(G45) -> 38 | G46: =F46+E46 -> 50 | H46: =I46-E46 -> 58 | I46: =MAX(G42:G49) -> 70 | J46: =H46-F46 -> 20 | K46: =MAX(G42:G49)-G46 -> 20 | L46: =IF(ABS(J46)<0.0001,"SÍ","NO") -> NO
A47: ='03_CPM_Obra_Gruesa'!A153 -> I | B47: ='03_CPM_Obra_Gruesa'!B153 -> 2.6 | C47: ='03_CPM_Obra_Gruesa'!D153 -> Estructura metálica y viga reticulada | D47: G | E47: ='03_CPM_Obra_Gruesa'!E153 -> 20 | F47: =MAX(G45) -> 38 | G47: =F47+E47 -> 58 | H47: =I47-E47 -> 38 | I47: =MIN(H48) -> 58 | J47: =H47-F47 -> 0 | K47: =MIN(F48)-G47 -> 0 | L47: =IF(ABS(J47)<0.0001,"SÍ","NO") -> SÍ
A48: ='03_CPM_Obra_Gruesa'!A154 -> J | B48: ='03_CPM_Obra_Gruesa'!B154 -> 2.7 | C48: ='03_CPM_Obra_Gruesa'!D154 -> Cubierta y hojalatería | D48: I | E48: ='03_CPM_Obra_Gruesa'!E154 -> 12 | F48: =MAX(G47) -> 58 | G48: =F48+E48 -> 70 | H48: =I48-E48 -> 58 | I48: =MAX(G42:G49) -> 70 | J48: =H48-F48 -> 0 | K48: =MAX(G42:G49)-G48 -> 0 | L48: =IF(ABS(J48)<0.0001,"SÍ","NO") -> SÍ
A49: ='03_CPM_Obra_Gruesa'!A155 -> K | B49: ='03_CPM_Obra_Gruesa'!B155 -> 2.8 | C49: ='03_CPM_Obra_Gruesa'!D155 -> Muros y tabiques Metalcon | D49: G | E49: ='03_CPM_Obra_Gruesa'!E155 -> 18 | F49: =MAX(G45) -> 38 | G49: =F49+E49 -> 56 | H49: =I49-E49 -> 52 | I49: =MAX(G42:G49) -> 70 | J49: =H49-F49 -> 14 | K49: =MAX(G42:G49)-G49 -> 14 | L49: =IF(ABS(J49)<0.0001,"SÍ","NO") -> NO
A51: FT = IT + duración. IT = máximo FT de las predecesoras. FTa = mínimo ITa de las sucesoras. ITa = FTa − duración. HT = ITa − IT. PERT usa te = (to + 4 tm + tp) / 6 sin redondear los cálculos. Las capturas son estáticas: regenerarlas después de cambiar entradas.
A64: CPM DEL PROYECTO COMPLETO - COMPLEMENTO DE COORDINACIÓN
A65: Plazo 150.00 días. Ruta crítica: A → B → D → E → F → G → I → J → L → Q → R → T → V. Se mantienen todas las entradas externas y frentes del proyecto.
A101: DESGLOSE DE COBERTURA Y TRAZABILIDAD POR PARTIDA
A102: Cada subpartida se ejecuta dentro de su paquete. No tiene duración individual calculada en el Paso 2. Los tiempos siguientes son del paquete, no un rendimiento propio.
A103: Código presupuesto | B103: Nodo | C103: Partida presupuestaria | D103: Unidad | E103: Cantidad | F103: Duración paquete | G103: IT paquete | H103: FT paquete | I103: ITa paquete | J103: FTa paquete | K103: HT paquete | L103: Crítica paquete
A104: ='06_Presupuesto'!A183 -> B.1.1.1 | B104: ='06_Presupuesto'!B183 -> D | C104: ='06_Presupuesto'!C183 -> Excavaciones | D104: ='06_Presupuesto'!D183 -> M3 | E104: ='06_Presupuesto'!E183 -> 15 | F104: =E42 -> 11 | G104: =F42 -> 0 | H104: =G42 -> 11 | I104: =H42 -> 0 | J104: =I42 -> 11 | K104: =J42 -> 0 | L104: =L42 -> SÍ
A105: ='06_Presupuesto'!A184 -> B.1.1.2 | B105: ='06_Presupuesto'!B184 -> F | C105: ='06_Presupuesto'!C184 -> Emplantillado | D105: ='06_Presupuesto'!D184 -> M2 | E105: ='06_Presupuesto'!E184 -> 23 | F105: =E44 -> 5 | G105: =F44 -> 20 | H105: =G44 -> 25 | I105: =H44 -> 20 | J105: =I44 -> 25 | K105: =J44 -> 0 | L105: =L44 -> SÍ
A106: ='06_Presupuesto'!A185 -> B.1.1.3 | B106: ='06_Presupuesto'!B185 -> G | C106: ='06_Presupuesto'!C185 -> Cimientos | D106: ='06_Presupuesto'!D185 -> M3 | E106: ='06_Presupuesto'!E185 -> 14 | F106: =E45 -> 13 | G106: =F45 -> 25 | H106: =G45 -> 38 | I106: =H45 -> 25 | J106: =I45 -> 38 | K106: =J45 -> 0 | L106: =L45 -> SÍ
A107: ='06_Presupuesto'!A186 -> B.1.2.1 | B107: ='06_Presupuesto'!B186 -> E | C107: ='06_Presupuesto'!C186 -> Preparación de la subrasante | D107: ='06_Presupuesto'!D186 -> M2 | E107: ='06_Presupuesto'!E186 -> 143 | F107: =E43 -> 9 | G107: =F43 -> 11 | H107: =G43 -> 20 | I107: =H43 -> 11 | J107: =I43 -> 20 | K107: =J43 -> 0 | L107: =L43 -> SÍ
A108: ='06_Presupuesto'!A187 -> B.1.2.2 | B108: ='06_Presupuesto'!B187 -> E | C108: ='06_Presupuesto'!C187 -> Base Estabilizada e=8cm | D108: ='06_Presupuesto'!D187 -> M3 | E108: ='06_Presupuesto'!E187 -> 11.44 | F108: =E43 -> 9 | G108: =F43 -> 11 | H108: =G43 -> 20 | I108: =H43 -> 11 | J108: =I43 -> 20 | K108: =J43 -> 0 | L108: =L43 -> SÍ
A109: ='06_Presupuesto'!A188 -> B.1.2.3 | B109: ='06_Presupuesto'!B188 -> H | C109: ='06_Presupuesto'!C188 -> Impermeabilización film de Polietileno e=0,10mm | D109: ='06_Presupuesto'!D188 -> M2 | E109: ='06_Presupuesto'!E188 -> 143 | F109: =E46 -> 12 | G109: =F46 -> 38 | H109: =G46 -> 50 | I109: =H46 -> 58 | J109: =I46 -> 70 | K109: =J46 -> 20 | L109: =L46 -> NO
A110: ='06_Presupuesto'!A189 -> B.1.2.4 | B110: ='06_Presupuesto'!B189 -> H | C110: ='06_Presupuesto'!C189 -> Cama de Ripio e=8cm | D110: ='06_Presupuesto'!D189 -> M3 | E110: ='06_Presupuesto'!E189 -> 11.44 | F110: =E46 -> 12 | G110: =F46 -> 38 | H110: =G46 -> 50 | I110: =H46 -> 58 | J110: =I46 -> 70 | K110: =J46 -> 20 | L110: =L46 -> NO
A111: ='06_Presupuesto'!A190 -> B.1.2.5 | B111: ='06_Presupuesto'!B190 -> H | C111: ='06_Presupuesto'!C190 -> Malla Acma C-92 | D111: ='06_Presupuesto'!D190 -> M2 | E111: ='06_Presupuesto'!E190 -> 143 | F111: =E46 -> 12 | G111: =F46 -> 38 | H111: =G46 -> 50 | I111: =H46 -> 58 | J111: =I46 -> 70 | K111: =J46 -> 20 | L111: =L46 -> NO
A112: ='06_Presupuesto'!A191 -> B.1.2.6 | B112: ='06_Presupuesto'!B191 -> H | C112: ='06_Presupuesto'!C191 -> Radier e= 7cm | D112: ='06_Presupuesto'!D191 -> M2 | E112: ='06_Presupuesto'!E191 -> 143 | F112: =E46 -> 12 | G112: =F46 -> 38 | H112: =G46 -> 50 | I112: =H46 -> 58 | J112: =I46 -> 70 | K112: =J46 -> 20 | L112: =L46 -> NO
A113: ='06_Presupuesto'!A192 -> B.1.3.1 | B113: ='06_Presupuesto'!B192 -> E | C113: ='06_Presupuesto'!C192 -> Estabilizado Compactado e=20cm | D113: ='06_Presupuesto'!D192 -> M3 | E113: ='06_Presupuesto'!E192 -> 18.65 | F113: =E43 -> 9 | G113: =F43 -> 11 | H113: =G43 -> 20 | I113: =H43 -> 11 | J113: =I43 -> 20 | K113: =J43 -> 0 | L113: =L43 -> SÍ
A114: ='06_Presupuesto'!A193 -> B.1.3.2 | B114: ='06_Presupuesto'!B193 -> E | C114: ='06_Presupuesto'!C193 -> Ripio Compactado e=10cm | D114: ='06_Presupuesto'!D193 -> M3 | E114: ='06_Presupuesto'!E193 -> 9.324 | F114: =E43 -> 9 | G114: =F43 -> 11 | H114: =G43 -> 20 | I114: =H43 -> 11 | J114: =I43 -> 20 | K114: =J43 -> 0 | L114: =L43 -> SÍ
A115: ='06_Presupuesto'!A194 -> B.1.3.3 | B115: ='06_Presupuesto'!B194 -> H | C115: ='06_Presupuesto'!C194 -> Polietileno e=0,15mm | D115: ='06_Presupuesto'!D194 -> M2 | E115: ='06_Presupuesto'!E194 -> 93.24 | F115: =E46 -> 12 | G115: =F46 -> 38 | H115: =G46 -> 50 | I115: =H46 -> 58 | J115: =I46 -> 70 | K115: =J46 -> 20 | L115: =L46 -> NO
A116: ='06_Presupuesto'!A195 -> B.1.3.4 | B116: ='06_Presupuesto'!B195 -> H | C116: ='06_Presupuesto'!C195 -> Radier e=10cm | D116: ='06_Presupuesto'!D195 -> M2 | E116: ='06_Presupuesto'!E195 -> 93.24 | F116: =E46 -> 12 | G116: =F46 -> 38 | H116: =G46 -> 50 | I116: =H46 -> 58 | J116: =I46 -> 70 | K116: =J46 -> 20 | L116: =L46 -> NO
A117: ='06_Presupuesto'!A196 -> B.1.4.1 | B117: ='06_Presupuesto'!B196 -> K | C117: ='06_Presupuesto'!C196 -> Estructura de Metalcon en Muros | D117: ='06_Presupuesto'!D196 -> M2 | E117: ='06_Presupuesto'!E196 -> 236 | F117: =E49 -> 18 | G117: =F49 -> 38 | H117: =G49 -> 56 | I117: =H49 -> 52 | J117: =I49 -> 70 | K117: =J49 -> 14 | L117: =L49 -> NO
A118: ='06_Presupuesto'!A197 -> B.1.4.2 | B118: ='06_Presupuesto'!B197 -> K | C118: ='06_Presupuesto'!C197 -> Planchas de OSB e=11.1mm | D118: ='06_Presupuesto'!D197 -> M2 | E118: ='06_Presupuesto'!E197 -> 153 | F118: =E49 -> 18 | G118: =F49 -> 38 | H118: =G49 -> 56 | I118: =H49 -> 52 | J118: =I49 -> 70 | K118: =J49 -> 14 | L118: =L49 -> NO
A119: ='06_Presupuesto'!A198 -> B.1.4.3 | B119: ='06_Presupuesto'!B198 -> K | C119: ='06_Presupuesto'!C198 -> Forro Exterior | D119: ='06_Presupuesto'!D198 -> M2 | E119: ='06_Presupuesto'!E198 -> 153 | F119: =E49 -> 18 | G119: =F49 -> 38 | H119: =G49 -> 56 | I119: =H49 -> 52 | J119: =I49 -> 70 | K119: =J49 -> 14 | L119: =L49 -> NO
A120: ='06_Presupuesto'!A199 -> B.1.4.4 | B120: ='06_Presupuesto'!B199 -> K | C120: ='06_Presupuesto'!C199 -> Forro Interior Volcanita y Aleros Exteriores | D120: ='06_Presupuesto'!D199 -> M2 | E120: ='06_Presupuesto'!E199 -> 180 | F120: =E49 -> 18 | G120: =F49 -> 38 | H120: =G49 -> 56 | I120: =H49 -> 52 | J120: =I49 -> 70 | K120: =J49 -> 14 | L120: =L49 -> NO
A121: ='06_Presupuesto'!A200 -> B.1.4.5 | B121: ='06_Presupuesto'!B200 -> K | C121: ='06_Presupuesto'!C200 -> Forro Interior Fibrocemento | D121: ='06_Presupuesto'!D200 -> M2 | E121: ='06_Presupuesto'!E200 -> 65 | F121: =E49 -> 18 | G121: =F49 -> 38 | H121: =G49 -> 56 | I121: =H49 -> 52 | J121: =I49 -> 70 | K121: =J49 -> 14 | L121: =L49 -> NO
A122: ='06_Presupuesto'!A201 -> B.1.5.1 | B122: ='06_Presupuesto'!B201 -> I | C122: ='06_Presupuesto'!C201 -> Cerchas y Costaneras de Acero Galvanizado | D122: ='06_Presupuesto'!D201 -> M2 | E122: ='06_Presupuesto'!E201 -> 78.61 | F122: =E47 -> 20 | G122: =F47 -> 38 | H122: =G47 -> 58 | I122: =H47 -> 38 | J122: =I47 -> 58 | K122: =J47 -> 0 | L122: =L47 -> SÍ
A123: ='06_Presupuesto'!A202 -> B.1.6.1 | B123: ='06_Presupuesto'!B202 -> J | C123: ='06_Presupuesto'!C202 -> Aislación Papel Impermeabilizante | D123: ='06_Presupuesto'!D202 -> M2 | E123: ='06_Presupuesto'!E202 -> 78.61 | F123: =E48 -> 12 | G123: =F48 -> 58 | H123: =G48 -> 70 | I123: =H48 -> 58 | J123: =I48 -> 70 | K123: =J48 -> 0 | L123: =L48 -> SÍ
...

Sheet 04_PERT_Terminaciones
A2: PERT DE TERMINACIONES - ES3 IND. 4
A3: PERT sectorial: 6 paquetes de programación asociados a 38 partidas presupuestarias de terminaciones. La correspondencia por partida se presenta desde la fila 103.
A5: Red sectorial autónoma: día 0 local, 57.50 días. Entradas externas Q depende de L, K; U depende de J, K; V depende de P se conservan en la red total, no en esta subred. No sumar su duración al plazo total.
A7: Lectura: arriba IT (inicio temprano) / FT (término temprano); abajo ITa (inicio tardío) / FTa (término tardío). Rojo: ruta crítica. Azul: actividades con holgura.
A51: TABLA SECTORIAL - RUTA CRÍTICA Q → R → T → V
A52: Nodo | B52: EDT | C52: Partida / paquete | D52: Predecesoras locales | E52: Duración (d) | F52: IT | G52: FT | H52: ITa | I52: FTa | J52: HT | K52: HL | L52: Crítica
A53: ='04_PERT_Terminaciones'!A171 -> Q | B53: ='04_PERT_Terminaciones'!B171 -> 4.1 | C53: ='04_PERT_Terminaciones'!D171 -> Revestimientos interiores | D53: — | E53: ='04_PERT_Terminaciones'!I171 -> 16.666667 | F53: =0 -> 0 | G53: =F53+E53 -> 16.666667 | H53: =I53-E53 -> 0 | I53: =MIN(H54,H55) -> 16.666667 | J53: =H53-F53 -> 0 | K53: =MIN(F54,F55)-G53 -> 0 | L53: =IF(ABS(J53)<0.0001,"SÍ","NO") -> SÍ
A54: ='04_PERT_Terminaciones'!A172 -> R | B54: ='04_PERT_Terminaciones'!B172 -> 4.2 | C54: ='04_PERT_Terminaciones'!D172 -> Cielos y elementos complementarios | D54: Q | E54: ='04_PERT_Terminaciones'!I172 -> 12.5 | F54: =MAX(G53) -> 16.666667 | G54: =F54+E54 -> 29.166667 | H54: =I54-E54 -> 16.666667 | I54: =MIN(H56) -> 29.166667 | J54: =H54-F54 -> 0 | K54: =MIN(F56)-G54 -> 0 | L54: =IF(ABS(J54)<0.0001,"SÍ","NO") -> SÍ
A55: ='04_PERT_Terminaciones'!A173 -> S | B55: ='04_PERT_Terminaciones'!B173 -> 4.3 | C55: ='04_PERT_Terminaciones'!D173 -> Pavimentos | D55: Q | E55: ='04_PERT_Terminaciones'!I173 -> 10.5 | F55: =MAX(G53) -> 16.666667 | G55: =F55+E55 -> 27.166667 | H55: =I55-E55 -> 18.666667 | I55: =MIN(H56) -> 29.166667 | J55: =H55-F55 -> 2 | K55: =MIN(F56)-G55 -> 2 | L55: =IF(ABS(J55)<0.0001,"SÍ","NO") -> NO
A56: ='04_PERT_Terminaciones'!A174 -> T | B56: ='04_PERT_Terminaciones'!B174 -> 4.4 | C56: ='04_PERT_Terminaciones'!D174 -> Pinturas interiores y exteriores | D56: R, S | E56: ='04_PERT_Terminaciones'!I174 -> 20.833333 | F56: =MAX(G54,G55) -> 29.166667 | G56: =F56+E56 -> 50 | H56: =I56-E56 -> 29.166667 | I56: =MIN(H58) -> 50 | J56: =H56-F56 -> 0 | K56: =MIN(F58)-G56 -> 0 | L56: =IF(ABS(J56)<0.0001,"SÍ","NO") -> SÍ
A57: ='04_PERT_Terminaciones'!A175 -> U | B57: ='04_PERT_Terminaciones'!B175 -> 4.5 | C57: ='04_PERT_Terminaciones'!D175 -> Puertas, ventanas y quincallería | D57: — | E57: ='04_PERT_Terminaciones'!I175 -> 16.666667 | F57: =0 -> 0 | G57: =F57+E57 -> 16.666667 | H57: =I57-E57 -> 33.333333 | I57: =MIN(H58) -> 50 | J57: =H57-F57 -> 33.333333 | K57: =MIN(F58)-G57 -> 33.333333 | L57: =IF(ABS(J57)<0.0001,"SÍ","NO") -> NO
A58: ='04_PERT_Terminaciones'!A176 -> V | B58: ='04_PERT_Terminaciones'!B176 -> 4.6 | C58: ='04_PERT_Terminaciones'!D176 -> Limpieza, remates y entrega | D58: T, U | E58: ='04_PERT_Terminaciones'!I176 -> 7.5 | F58: =MAX(G56,G57) -> 50 | G58: =F58+E58 -> 57.5 | H58: =I58-E58 -> 50 | I58: =MAX(G53:G58) -> 57.5 | J58: =H58-F58 -> 0 | K58: =MAX(G53:G58)-G58 -> 0 | L58: =IF(ABS(J58)<0.0001,"SÍ","NO") -> SÍ
A60: FT = IT + duración. IT = máximo FT de las predecesoras. FTa = mínimo ITa de las sucesoras. ITa = FTa − duración. HT = ITa − IT. PERT usa te = (to + 4 tm + tp) / 6 sin redondear los cálculos. Las capturas son estáticas: regenerarlas después de cambiar entradas.
A64: PERT DEL PROYECTO COMPLETO - COMPLEMENTO DE COORDINACIÓN
A65: Plazo 155.17 días. Ruta crítica: A → B → D → E → F → G → I → J → L → Q → R → T → V. Se mantienen todas las entradas externas y frentes del proyecto.
A101: DESGLOSE DE COBERTURA Y TRAZABILIDAD POR PARTIDA
A102: Cada subpartida se ejecuta dentro de su paquete. No tiene duración individual calculada en el Paso 2. Los tiempos siguientes son del paquete, no un rendimiento propio.
A103: Código presupuesto | B103: Nodo | C103: Partida presupuestaria | D103: Unidad | E103: Cantidad | F103: Duración paquete | G103: IT paquete | H103: FT paquete | I103: ITa paquete | J103: FTa paquete | K103: HT paquete | L103: Crítica paquete
A104: ='06_Presupuesto'!A205 -> B.2.1.1 | B104: ='06_Presupuesto'!B205 -> Q | C104: ='06_Presupuesto'!C205 -> Aislante Térmico Para Muros | D104: ='06_Presupuesto'!D205 -> M2 | E104: ='06_Presupuesto'!E205 -> 236 | F104: =E53 -> 16.666667 | G104: =F53 -> 0 | H104: =G53 -> 16.666667 | I104: =H53 -> 0 | J104: =I53 -> 16.666667 | K104: =J53 -> 0 | L104: =L53 -> SÍ
A105: ='06_Presupuesto'!A206 -> B.2.1.2 | B105: ='06_Presupuesto'!B206 -> R | C105: ='06_Presupuesto'!C206 -> Aislante Térmico Para Cielo | D105: ='06_Presupuesto'!D206 -> M2 | E105: ='06_Presupuesto'!E206 -> 78.61 | F105: =E54 -> 12.5 | G105: =F54 -> 16.666667 | H105: =G54 -> 29.166667 | I105: =H54 -> 16.666667 | J105: =I54 -> 29.166667 | K105: =J54 -> 0 | L105: =L54 -> SÍ
A106: ='06_Presupuesto'!A207 -> B.2.1.3 | B106: ='06_Presupuesto'!B207 -> S | C106: ='06_Presupuesto'!C207 -> Impermeabilización Bajo Pavimentos | D106: ='06_Presupuesto'!D207 -> M2 | E106: ='06_Presupuesto'!E207 -> 85 | F106: =E55 -> 10.5 | G106: =F55 -> 16.666667 | H106: =G55 -> 27.166667 | I106: =H55 -> 18.666667 | J106: =I55 -> 29.166667 | K106: =J55 -> 2 | L106: =L55 -> NO
A107: ='06_Presupuesto'!A208 -> B.2.2/a) | B107: ='06_Presupuesto'!B208 -> R | C107: ='06_Presupuesto'!C208 -> Yeso Cartón RH | D107: ='06_Presupuesto'!D208 -> M2 | E107: ='06_Presupuesto'!E208 -> 34 | F107: =E54 -> 12.5 | G107: =F54 -> 16.666667 | H107: =G54 -> 29.166667 | I107: =H54 -> 16.666667 | J107: =I54 -> 29.166667 | K107: =J54 -> 0 | L107: =L54 -> SÍ
A108: ='06_Presupuesto'!A209 -> B.2.3/a) | B108: ='06_Presupuesto'!B209 -> R | C108: ='06_Presupuesto'!C209 -> Yeso Cartón | D108: ='06_Presupuesto'!D209 -> M2 | E108: ='06_Presupuesto'!E209 -> 50 | F108: =E54 -> 12.5 | G108: =F54 -> 16.666667 | H108: =G54 -> 29.166667 | I108: =H54 -> 16.666667 | J108: =I54 -> 29.166667 | K108: =J54 -> 0 | L108: =L54 -> SÍ
A109: ='06_Presupuesto'!A214 -> B.2.5.1 | B109: ='06_Presupuesto'!B214 -> Q | C109: ='06_Presupuesto'!C214 -> Cerámicos Muros | D109: ='06_Presupuesto'!D214 -> M2 | E109: ='06_Presupuesto'!E214 -> 70 | F109: =E53 -> 16.666667 | G109: =F53 -> 0 | H109: =G53 -> 16.666667 | I109: =H53 -> 0 | J109: =I53 -> 16.666667 | K109: =J53 -> 0 | L109: =L53 -> SÍ
A110: ='06_Presupuesto'!A215 -> B.2.5.2 | B110: ='06_Presupuesto'!B215 -> S | C110: ='06_Presupuesto'!C215 -> Cerámicos Pisos | D110: ='06_Presupuesto'!D215 -> M2 | E110: ='06_Presupuesto'!E215 -> 84 | F110: =E55 -> 10.5 | G110: =F55 -> 16.666667 | H110: =G55 -> 27.166667 | I110: =H55 -> 18.666667 | J110: =I55 -> 29.166667 | K110: =J55 -> 2 | L110: =L55 -> NO
A111: ='06_Presupuesto'!A216 -> B.2.6.1 | B111: ='06_Presupuesto'!B216 -> T | C111: ='06_Presupuesto'!C216 -> Pintura Puertas Exteriores Esmalte Sintético | D111: ='06_Presupuesto'!D216 -> M2 | E111: ='06_Presupuesto'!E216 -> 35 | F111: =E56 -> 20.833333 | G111: =F56 -> 29.166667 | H111: =G56 -> 50 | I111: =H56 -> 29.166667 | J111: =I56 -> 50 | K111: =J56 -> 0 | L111: =L56 -> SÍ
A112: ='06_Presupuesto'!A217 -> B.2.6.2 | B112: ='06_Presupuesto'!B217 -> T | C112: ='06_Presupuesto'!C217 -> Pintura Interior | D112: ='06_Presupuesto'!D217 -> M2 | E112: ='06_Presupuesto'!E217 -> 250 | F112: =E56 -> 20.833333 | G112: =F56 -> 29.166667 | H112: =G56 -> 50 | I112: =H56 -> 29.166667 | J112: =I56 -> 50 | K112: =J56 -> 0 | L112: =L56 -> SÍ
A113: ='06_Presupuesto'!A218 -> B.2.7.1/a) | B113: ='06_Presupuesto'!B218 -> U | C113: ='06_Presupuesto'!C218 -> P1 / Madera Puertas | D113: ='06_Presupuesto'!D218 -> UNI | E113: ='06_Presupuesto'!E218 -> 1 | F113: =E57 -> 16.666667 | G113: =F57 -> 0 | H113: =G57 -> 16.666667 | I113: =H57 -> 33.333333 | J113: =I57 -> 50 | K113: =J57 -> 33.333333 | L113: =L57 -> NO
A114: ='06_Presupuesto'!A219 -> B.2.7.1/b) | B114: ='06_Presupuesto'!B219 -> U | C114: ='06_Presupuesto'!C219 -> P2 / Madera Puertas | D114: ='06_Presupuesto'!D219 -> UNI | E114: ='06_Presupuesto'!E219 -> 2 | F114: =E57 -> 16.666667 | G114: =F57 -> 0 | H114: =G57 -> 16.666667 | I114: =H57 -> 33.333333 | J114: =I57 -> 50 | K114: =J57 -> 33.333333 | L114: =L57 -> NO
A115: ='06_Presupuesto'!A220 -> B.2.7.1/c) | B115: ='06_Presupuesto'!B220 -> U | C115: ='06_Presupuesto'!C220 -> P3 / Madera Puertas | D115: ='06_Presupuesto'!D220 -> UNI | E115: ='06_Presupuesto'!E220 -> 3 | F115: =E57 -> 16.666667 | G115: =F57 -> 0 | H115: =G57 -> 16.666667 | I115: =H57 -> 33.333333 | J115: =I57 -> 50 | K115: =J57 -> 33.333333 | L115: =L57 -> NO
A116: ='06_Presupuesto'!A221 -> B.2.7.1/d) | B116: ='06_Presupuesto'!B221 -> U | C116: ='06_Presupuesto'!C221 -> P4 / Madera Puertas | D116: ='06_Presupuesto'!D221 -> UNI | E116: ='06_Presupuesto'!E221 -> 1 | F116: =E57 -> 16.666667 | G116: =F57 -> 0 | H116: =G57 -> 16.666667 | I116: =H57 -> 33.333333 | J116: =I57 -> 50 | K116: =J57 -> 33.333333 | L116: =L57 -> NO
A117: ='06_Presupuesto'!A222 -> B.2.7.2/a) | B117: ='06_Presupuesto'!B222 -> U | C117: ='06_Presupuesto'!C222 -> P1 / Marcos | D117: ='06_Presupuesto'!D222 -> ML | E117: ='06_Presupuesto'!E222 -> 6 | F117: =E57 -> 16.666667 | G117: =F57 -> 0 | H117: =G57 -> 16.666667 | I117: =H57 -> 33.333333 | J117: =I57 -> 50 | K117: =J57 -> 33.333333 | L117: =L57 -> NO
A118: ='06_Presupuesto'!A223 -> B.2.7.2/b) | B118: ='06_Presupuesto'!B223 -> U | C118: ='06_Presupuesto'!C223 -> P2 / Marcos | D118: ='06_Presupuesto'!D223 -> ML | E118: ='06_Presupuesto'!E223 -> 10 | F118: =E57 -> 16.666667 | G118: =F57 -> 0 | H118: =G57 -> 16.666667 | I118: =H57 -> 33.333333 | J118: =I57 -> 50 | K118: =J57 -> 33.333333 | L118: =L57 -> NO
A119: ='06_Presupuesto'!A224 -> B.2.7.2/c) | B119: ='06_Presupuesto'!B224 -> U | C119: ='06_Presupuesto'!C224 -> P3 / Marcos | D119: ='06_Presupuesto'!D224 -> ML | E119: ='06_Presupuesto'!E224 -> 15 | F119: =E57 -> 16.666667 | G119: =F57 -> 0 | H119: =G57 -> 16.666667 | I119: =H57 -> 33.333333 | J119: =I57 -> 50 | K119: =J57 -> 33.333333 | L119: =L57 -> NO
A120: ='06_Presupuesto'!A225 -> B.2.7.2/d) | B120: ='06_Presupuesto'!B225 -> U | C120: ='06_Presupuesto'!C225 -> P4 / Marcos | D120: ='06_Presupuesto'!D225 -> ML | E120: ='06_Presupuesto'!E225 -> 5 | F120: =E57 -> 16.666667 | G120: =F57 -> 0 | H120: =G57 -> 16.666667 | I120: =H57 -> 33.333333 | J120: =I57 -> 50 | K120: =J57 -> 33.333333 | L120: =L57 -> NO
A121: ='06_Presupuesto'!A226 -> B.2.8/a) | B121: ='06_Presupuesto'!B226 -> U | C121: ='06_Presupuesto'!C226 -> Bisagras | D121: ='06_Presupuesto'!D226 -> UNI | E121: ='06_Presupuesto'!E226 -> 28 | F121: =E57 -> 16.666667 | G121: =F57 -> 0 | H121: =G57 -> 16.666667 | I121: =H57 -> 33.333333 | J121: =I57 -> 50 | K121: =J57 -> 33.333333 | L121: =L57 -> NO
A122: ='06_Presupuesto'!A227 -> B.2.8/b) | B122: ='06_Presupuesto'!B227 -> U | C122: ='06_Presupuesto'!C227 -> Topes de Goma | D122: ='06_Presupuesto'!D227 -> UNI | E122: ='06_Presupuesto'!E227 -> 8 | F122: =E57 -> 16.666667 | G122: =F57 -> 0 | H122: =G57 -> 16.666667 | I122: =H57 -> 33.333333 | J122: =I57 -> 50 | K122: =J57 -> 33.333333 | L122: =L57 -> NO
A123: ='06_Presupuesto'!A228 -> B.2.8/c) | B123: ='06_Presupuesto'!B228 -> U | C123: ='06_Presupuesto'!C228 -> Cerraduras | D123: ='06_Presupuesto'!D228 -> UNI | E123: ='06_Presupuesto'!E228 -> 7 | F123: =E57 -> 16.666667 | G123: =F57 -> 0 | H123: =G57 -> 16.666667 | I123: =H57 -> 33.333333 | J123: =I57 -> 50 | K123: =J57 -> 33.333333 | L123: =L57 -> NO
A124: ='06_Presupuesto'!A229 -> B.2.8/d) | B124: ='06_Presupuesto'!B229 -> U | C124: ='06_Presupuesto'!C229 -> Picaporte de Uñeta | D124: ='06_Presupuesto'!D229 -> UNI | E124: ='06_Presupuesto'!E229 -> 2 | F124: =E57 -> 16.666667 | G124: =F57 -> 0 | H124: =G57 -> 16.666667 | I124: =H57 -> 33.333333 | J124: =I57 -> 50 | K124: =J57 -> 33.333333 | L124: =L57 -> NO
A125: ='06_Presupuesto'!A230 -> B.2.9.1 | B125: ='06_Presupuesto'!B230 -> U | C125: ='06_Presupuesto'!C230 -> Ventanas Con Marco De Aluminio Blanco | D125: ='06_Presupuesto'!D230 -> M2 | E125: ='06_Presupuesto'!E230 -> 15 | F125: =E57 -> 16.666667 | G125: =F57 -> 0 | H125: =G57 -> 16.666667 | I125: =H57 -> 33.333333 | J125: =I57 -> 50 | K125: =J57 -> 33.333333 | L125: =L57 -> NO
...

Sheet 05_Carta_Gantt
A1: PASO 5 · CARTA GANTT MAESTRA · ES3 IND. 5
A2: Inicio 02-11-2026. Las fechas se enlazan al CPM. Días corridos incluyen fines de semana; no se asume trabajo diario de cada persona.
A5: Inicio del plan | B5: ='02_Rendimientos'!B79 -> 46328 | D5: Duración total | E5: ='03_CPM_Obra_Gruesa'!H167 -> 150 | G5: Término | H5: =B5+E5-1 -> 46477
A8: EDT | B8: Macro-etapa | C8: Nombre de actividad | D8: Duración (d) | E8: Fecha inicio | F8: Fecha fin | G8: Predecesoras | H8: Crítica CPM | I8: Sucesoras | J8: Control / frente | K8: =$B$5+0 -> 46328 | L8: =$B$5+7 -> 46335 | M8: =$B$5+14 -> 46342 | N8: =$B$5+21 -> 46349 | O8: =$B$5+28 -> 46356 | P8: =$B$5+35 -> 46363 | Q8: =$B$5+42 -> 46370 | R8: =$B$5+49 -> 46377 | S8: =$B$5+56 -> 46384 | T8: =$B$5+63 -> 46391 | U8: =$B$5+70 -> 46398 | V8: =$B$5+77 -> 46405 | W8: =$B$5+84 -> 46412 | X8: =$B$5+91 -> 46419 | Y8: =$B$5+98 -> 46426 | Z8: =$B$5+105 -> 46433 | AA8: =$B$5+112 -> 46440 | AB8: =$B$5+119 -> 46447 | AC8: =$B$5+126 -> 46454 | AD8: =$B$5+133 -> 46461 | AE8: =$B$5+140 -> 46468 | AF8: =$B$5+147 -> 46475
A9: 1.1 | B9: Instalación de faenas | C9: Instalación de faenas y cierre perimetral | D9: ='03_CPM_Obra_Gruesa'!E145 -> 6 | E9: =$B$5+'03_CPM_Obra_Gruesa'!G145 -> 46328 | F9: =$B$5+'03_CPM_Obra_Gruesa'!H145-1 -> 46333 | G9: — | H9: ='03_CPM_Obra_Gruesa'!M145 -> SÍ | I9: B, C | J9: Programación por frente paralelo
A10: 1.2 | B10: Instalación de faenas | C10: Replanteo y nivelación del área de trabajo | D10: ='03_CPM_Obra_Gruesa'!E146 -> 5 | E10: =$B$5+'03_CPM_Obra_Gruesa'!G146 -> 46334 | F10: =$B$5+'03_CPM_Obra_Gruesa'!H146-1 -> 46338 | G10: A | H10: ='03_CPM_Obra_Gruesa'!M146 -> SÍ | I10: D | J10: Programación por frente paralelo
A11: 1.3 | B11: Instalación de faenas | C11: Servicios provisorios y habilitación de instalaciones | D11: ='03_CPM_Obra_Gruesa'!E147 -> 10 | E11: =$B$5+'03_CPM_Obra_Gruesa'!G147 -> 46334 | F11: =$B$5+'03_CPM_Obra_Gruesa'!H147-1 -> 46343 | G11: A | H11: ='03_CPM_Obra_Gruesa'!M147 -> NO | I11: FIN | J11: Programación por frente paralelo
A12: 2.1 | B12: Obra Gruesa | C12: Excavación y retiro de material | D12: ='03_CPM_Obra_Gruesa'!E148 -> 11 | E12: =$B$5+'03_CPM_Obra_Gruesa'!G148 -> 46339 | F12: =$B$5+'03_CPM_Obra_Gruesa'!H148-1 -> 46349 | G12: B | H12: ='03_CPM_Obra_Gruesa'!M148 -> SÍ | I12: E | J12: Programación por frente paralelo
A13: 2.2 | B13: Obra Gruesa | C13: Relleno, humectación y compactación | D13: ='03_CPM_Obra_Gruesa'!E149 -> 9 | E13: =$B$5+'03_CPM_Obra_Gruesa'!G149 -> 46350 | F13: =$B$5+'03_CPM_Obra_Gruesa'!H149-1 -> 46358 | G13: D | H13: ='03_CPM_Obra_Gruesa'!M149 -> SÍ | I13: F, N | J13: Programación por frente paralelo
A14: 2.3 | B14: Obra Gruesa | C14: Emplantillado de hormigón | D14: ='03_CPM_Obra_Gruesa'!E150 -> 5 | E14: =$B$5+'03_CPM_Obra_Gruesa'!G150 -> 46359 | F14: =$B$5+'03_CPM_Obra_Gruesa'!H150-1 -> 46363 | G14: E | H14: ='03_CPM_Obra_Gruesa'!M150 -> SÍ | I14: G | J14: Programación por frente paralelo
A15: 2.4 | B15: Obra Gruesa | C15: Fundaciones de hormigón armado | D15: ='03_CPM_Obra_Gruesa'!E151 -> 13 | E15: =$B$5+'03_CPM_Obra_Gruesa'!G151 -> 46364 | F15: =$B$5+'03_CPM_Obra_Gruesa'!H151-1 -> 46376 | G15: F | H15: ='03_CPM_Obra_Gruesa'!M151 -> SÍ | I15: H, I, K | J15: Programación por frente paralelo
A16: 2.5 | B16: Obra Gruesa | C16: Radier y losas de hormigón | D16: ='03_CPM_Obra_Gruesa'!E152 -> 12 | E16: =$B$5+'03_CPM_Obra_Gruesa'!G152 -> 46377 | F16: =$B$5+'03_CPM_Obra_Gruesa'!H152-1 -> 46388 | G16: G | H16: ='03_CPM_Obra_Gruesa'!M152 -> NO | I16: L | J16: Programación por frente paralelo
A17: 2.6 | B17: Obra Gruesa | C17: Estructura metálica y viga reticulada | D17: ='03_CPM_Obra_Gruesa'!E153 -> 20 | E17: =$B$5+'03_CPM_Obra_Gruesa'!G153 -> 46377 | F17: =$B$5+'03_CPM_Obra_Gruesa'!H153-1 -> 46396 | G17: G | H17: ='03_CPM_Obra_Gruesa'!M153 -> SÍ | I17: J, L | J17: Programación por frente paralelo
A18: 2.7 | B18: Obra Gruesa | C18: Cubierta y hojalatería | D18: ='03_CPM_Obra_Gruesa'!E154 -> 12 | E18: =$B$5+'03_CPM_Obra_Gruesa'!G154 -> 46397 | F18: =$B$5+'03_CPM_Obra_Gruesa'!H154-1 -> 46408 | G18: I | H18: ='03_CPM_Obra_Gruesa'!M154 -> SÍ | I18: L, U | J18: Programación por frente paralelo
A19: 2.8 | B19: Obra Gruesa | C19: Muros y tabiques Metalcon | D19: ='03_CPM_Obra_Gruesa'!E155 -> 18 | E19: =$B$5+'03_CPM_Obra_Gruesa'!G155 -> 46377 | F19: =$B$5+'03_CPM_Obra_Gruesa'!H155-1 -> 46394 | G19: G | H19: ='03_CPM_Obra_Gruesa'!M155 -> NO | I19: L, M, Q, U | J19: Programación por frente paralelo
A20: 3.1 | B20: Instalaciones | C20: Instalación eléctrica interior | D20: ='03_CPM_Obra_Gruesa'!E156 -> 14 | E20: =$B$5+'03_CPM_Obra_Gruesa'!G156 -> 46409 | F20: =$B$5+'03_CPM_Obra_Gruesa'!H156-1 -> 46422 | G20: H - I - J - K | H20: ='03_CPM_Obra_Gruesa'!M156 -> SÍ | I20: P, Q | J20: Programación por frente paralelo
... A30: 4.6 | B30: Terminaciones | C30: Limpieza, remates y entrega | D30: ='03_CPM_Obra_Gruesa'!E166 -> 7 | E30: =$B$5+'03_CPM_Obra_Gruesa'!G166 -> 46471 | F30: =$B$5+'03_CPM_Obra_Gruesa'!H166-1 -> 46477 | G30: T - U - P | H30: ='03_CPM_Obra_Gruesa'!M166 -> SÍ | I30: FIN | J30: Programación por frente paralelo
A33: RESUMEN POR MACRO-ETAPA
A34: Macro-etapa | B34: Fecha inicio | C34: Fecha fin | D34: Intervalo (d) | E34: Peso de referencia | F34: Interpretación
A35: Instalación de faenas | B35: =MIN(E9:E11) -> 46328 | C35: =MAX(F9:F11) -> 46343 | D35: =C35-B35+1 -> 16 | E35: 0.08 | F35: Etapas solapadas; no sumar sus intervalos.
A36: Obra Gruesa | B36: =MIN(E12:E19) -> 46339 | C36: =MAX(F12:F19) -> 46408 | D36: =C36-B36+1 -> 70 | E36: 0.38 | F36: Etapas solapadas; no sumar sus intervalos.
A37: Instalaciones | B37: =MIN(E20:E24) -> 46359 | C37: =MAX(F20:F24) -> 46430 | D37: =C37-B37+1 -> 72 | E37: 0.22 | F37: Etapas solapadas; no sumar sus intervalos.
A38: Terminaciones | B38: =MIN(E25:E30) -> 46409 | C38: =MAX(F25:F30) -> 46477 | D38: =C38-B38+1 -> 69 | E38: 0.32 | F38: Etapas solapadas; no sumar sus intervalos.
A40: Ponderaciones por macroetapa del programa base: 8% instalación de faenas, 38% obra gruesa, 22% instalaciones y 32% terminaciones. Las actividades se solapan según sus precedencias.

Sheet 06_Presupuesto
B1: PASO 6 · PRESUPUESTO DETALLADO Y COMPENSADO · ES3 IND. 6
B2: PRESUPUESTO DETALLADO Y COMPENSADO
B3: Sede Social El Bosque · Grupo 4 · 140 partidas · montos CLP · factor único aplicado a cada precio unitario
B5: FACTOR DE COMPENSACIÓN | I5: =(1+'02_Rendimientos'!B83+'02_Rendimientos'!B84)*(1+'02_Rendimientos'!B82) -> 1.4875 | K5: (1 + GG 15% + utilidad 10%) × (1 + IVA 19%)
B7: PRESUPUESTO NORMAL · COSTO DIRECTO NETO | K7: PRESUPUESTO COMPENSADO · PRECIO FINAL CON IVA
B8: Ítem | C8: Partida | D8: Unidad | E8: Cantidad | F8: P. unitario normal neto | G8: Subtotal normal neto | K8: Ítem | L8: Partida | M8: Unidad | N8: Cantidad | O8: P. unitario compensado | P8: Subtotal compensado
B9: ='06_Presupuesto'!A175 -> A.1.1/a) | C9: ='06_Presupuesto'!C175 -> Oficina (con servicios básicos) | D9: ='06_Presupuesto'!D175 -> UNI | E9: ='06_Presupuesto'!E175 -> 1 | F9: ='06_Presupuesto'!G175 -> 1764705.9 | G9: =E9*F9 -> 1764705.9 | K9: =B9 -> A.1.1/a) | L9: =C9 -> Oficina (con servicios básicos) | M9: =D9 -> UNI | N9: =E9 -> 1 | O9: =F9*$I$5 -> 2625000 | P9: =N9*O9 -> 2625000
B10: ='06_Presupuesto'!A176 -> A.1.1/b) | C10: ='06_Presupuesto'!C176 -> Bodega de Materiales | D10: ='06_Presupuesto'!D176 -> UNI | E10: ='06_Presupuesto'!E176 -> 1 | F10: ='06_Presupuesto'!G176 -> 1008403.4 | G10: =E10*F10 -> 1008403.4 | K10: =B10 -> A.1.1/b) | L10: =C10 -> Bodega de Materiales | M10: =D10 -> UNI | N10: =E10 -> 1 | O10: =F10*$I$5 -> 1500000 | P10: =N10*O10 -> 1500000
B11: ='06_Presupuesto'!A177 -> A.1.1/c) | C11: ='06_Presupuesto'!C177 -> Servicios higiénicos tipo químicos | D11: ='06_Presupuesto'!D177 -> UNI | E11: ='06_Presupuesto'!E177 -> 2 | F11: ='06_Presupuesto'!G177 -> 714285.71 | G11: =E11*F11 -> 1428571.4 | K11: =B11 -> A.1.1/c) | L11: =C11 -> Servicios higiénicos tipo químicos | M11: =D11 -> UNI | N11: =E11 -> 2 | O11: =F11*$I$5 -> 1062500 | P11: =N11*O11 -> 2125000
B12: ='06_Presupuesto'!A178 -> A.1.1/d) | C12: ='06_Presupuesto'!C178 -> Comedor | D12: ='06_Presupuesto'!D178 -> M2 | E12: ='06_Presupuesto'!E178 -> 10 | F12: ='06_Presupuesto'!G178 -> 71428.571 | G12: =E12*F12 -> 714285.71 | K12: =B12 -> A.1.1/d) | L12: =C12 -> Comedor | M12: =D12 -> M2 | N12: =E12 -> 10 | O12: =F12*$I$5 -> 106250 | P12: =N12*O12 -> 1062500
B13: ='06_Presupuesto'!A179 -> A.1.2 | C13: ='06_Presupuesto'!C179 -> CIERRE PROVISORIO | D13: ='06_Presupuesto'!D179 -> ML | E13: ='06_Presupuesto'!E179 -> 84 | F13: ='06_Presupuesto'!G179 -> 12184.874 | G13: =E13*F13 -> 1023529.4 | K13: =B13 -> A.1.2 | L13: =C13 -> CIERRE PROVISORIO | M13: =D13 -> ML | N13: =E13 -> 84 | O13: =F13*$I$5 -> 18125 | P13: =N13*O13 -> 1522500
B14: ='06_Presupuesto'!A180 -> A.1.3 | C14: ='06_Presupuesto'!C180 -> LETRERO DE OBRA | D14: ='06_Presupuesto'!D180 -> UNI | E14: ='06_Presupuesto'!E180 -> 1 | F14: ='06_Presupuesto'!G180 -> 327731.09 | G14: =E14*F14 -> 327731.09 | K14: =B14 -> A.1.3 | L14: =C14 -> LETRERO DE OBRA | M14: =D14 -> UNI | N14: =E14 -> 1 | O14: =F14*$I$5 -> 487500 | P14: =N14*O14 -> 487500
B15: ='06_Presupuesto'!A181 -> A.2.1 | C15: ='06_Presupuesto'!C181 -> Limpieza y despeje de Terreno | D15: ='06_Presupuesto'!D181 -> M2 | E15: ='06_Presupuesto'!E181 -> 444.51 | F15: ='06_Presupuesto'!G181 -> 1848.7395 | G15: =E15*F15 -> 821783.19 | K15: =B15 -> A.2.1 | L15: =C15 -> Limpieza y despeje de Terreno | M15: =D15 -> M2 | N15: =E15 -> 444.51 | O15: =F15*$I$5 -> 2750 | P15: =N15*O15 -> 1222402.5
B16: ='06_Presupuesto'!A182 -> A.2.2 | C16: ='06_Presupuesto'!C182 -> Replanteo, trazado y niveles | D16: ='06_Presupuesto'!D182 -> M2 | E16: ='06_Presupuesto'!E182 -> 444.51 | F16: ='06_Presupuesto'!G182 -> 1764.7059 | G16: =E16*F16 -> 784429.41 | K16: =B16 -> A.2.2 | L16: =C16 -> Replanteo, trazado y niveles | M16: =D16 -> M2 | N16: =E16 -> 444.51 | O16: =F16*$I$5 -> 2625 | P16: =N16*O16 -> 1166838.7
B17: ='06_Presupuesto'!A183 -> B.1.1.1 | C17: ='06_Presupuesto'!C183 -> Excavaciones | D17: ='06_Presupuesto'!D183 -> M3 | E17: ='06_Presupuesto'!E183 -> 15 | F17: ='06_Presupuesto'!G183 -> 35294.118 | G17: =E17*F17 -> 529411.76 | K17: =B17 -> B.1.1.1 | L17: =C17 -> Excavaciones | M17: =D17 -> M3 | N17: =E17 -> 15 | O17: =F17*$I$5 -> 52500 | P17: =N17*O17 -> 787500
B18: ='06_Presupuesto'!A184 -> B.1.1.2 | C18: ='06_Presupuesto'!C184 -> Emplantillado | D18: ='06_Presupuesto'!D184 -> M2 | E18: ='06_Presupuesto'!E184 -> 23 | F18: ='06_Presupuesto'!G184 -> 16386.555 | G18: =E18*F18 -> 376890.76 | K18: =B18 -> B.1.1.2 | L18: =C18 -> Emplantillado | M18: =D18 -> M2 | N18: =E18 -> 23 | O18: =F18*$I$5 -> 24375 | P18: =N18*O18 -> 560625
B19: ='06_Presupuesto'!A185 -> B.1.1.3 | C19: ='06_Presupuesto'!C185 -> Cimientos | D19: ='06_Presupuesto'!D185 -> M3 | E19: ='06_Presupuesto'!E185 -> 14 | F19: ='06_Presupuesto'!G185 -> 189075.63 | G19: =E19*F19 -> 2647058.8 | K19: =B19 -> B.1.1.3 | L19: =C19 -> Cimientos | M19: =D19 -> M3 | N19: =E19 -> 14 | O19: =F19*$I$5 -> 281250 | P19: =N19*O19 -> 3937500
B20: ='06_Presupuesto'!A186 -> B.1.2.1 | C20: ='06_Presupuesto'!C186 -> Preparación de la subrasante | D20: ='06_Presupuesto'!D186 -> M2 | E20: ='06_Presupuesto'!E186 -> 143 | F20: ='06_Presupuesto'!G186 -> 2689.0756 | G20: =E20*F20 -> 384537.82 | K20: =B20 -> B.1.2.1 | L20: =C20 -> Preparación de la subrasante | M20: =D20 -> M2 | N20: =E20 -> 143 | O20: =F20*$I$5 -> 4000 | P20: =N20*O20 -> 572000
... B148: ='06_Presupuesto'!A314 -> G.2 | C148: ='06_Presupuesto'!C314 -> ASEO GENERAL | D148: ='06_Presupuesto'!D314 -> M2 | E148: ='06_Presupuesto'!E314 -> 444.51 | F148: ='06_Presupuesto'!G314 -> 1512.605 | G148: =E148*F148 -> 672368.07 | K148: =B148 -> G.2 | L148: =C148 -> ASEO GENERAL | M148: =D148 -> M2 | N148: =E148 -> 444.51 | O148: =F148*$I$5 -> 2250 | P148: =N148*O148 -> 1000147.5
B150: RESUMEN DEL COSTO NORMAL | K150: RESULTADO COMPENSADO
B151: Costo directo neto | G151: =SUM(G9:G148) -> 72760094 | K151: Total compensado | P151: =ROUND(SUM(P9:P148),0) -> 108230640
B152: Gastos generales (15%) | G152: =G151*'02_Rendimientos'!B83 -> 10914014 | K152: Factor aplicado | P152: =I5 -> 1.4875
B153: Utilidad ofertada (10%) | G153: =G151*'02_Rendimientos'!B84 -> 7276009.4 | K153: Diferencia con presupuesto ES3 | P153: =P151-'06_Presupuesto'!H323 -> 0
B154: Subtotal neto | G154: =SUM(G151:G153) -> 90950118 | K154: Presupuesto municipal | P154: ='02_Rendimientos'!B81 -> 114446607
B155: IVA (19%) | G155: =G154*'02_Rendimientos'!B82 -> 17280522 | K155: Ahorro de la propuesta | P155: =P154-P151 -> 6215967
B156: TOTAL DE LA OFERTA | G156: =ROUND(G154+G155,0) -> 108230640 | K156: Ahorro porcentual | P156: =P155/P154 -> 0.054313248
B159: Método: precio unitario compensado = precio unitario normal neto × factor. El subtotal se obtiene multiplicando por la cantidad.
B160: El factor incorpora gastos generales y utilidad sobre el costo directo; después aplica IVA. Los 140 ítems se desglosan a continuación en esta hoja.
B167: DESGLOSE BASE Y CRITERIOS DEL PRESUPUESTO COMPENSADO
A170: PASO 6 | PRESUPUESTO DETALLADO Y OFERTA COMPENSADA
A171: Cantidades: 5-PPTO..xlsx. Precios instalados estimados en CLP, orientados a una oferta competitiva; no son precios oficiales. GG 15%; utilidad propuesta 10% frente a 15% del formulario.
A172: Vista base del presupuesto, incorporada en esta misma hoja.
A174: Código municipal | B174: Act. CPM | C174: Partida / alcance | D174: Unidad | E174: Cantidad | F174: P.U. ref. con IVA | G174: P.U. neto | H174: Costo directo | I174: Venta neta | J174: Inicio plan | K174: Fin plan | L174: Fila fuente / pago
A175: A.1.1/a) | B175: A | C175: Oficina (con servicios básicos) | D175: UNI | E175: 1 | F175: 2100000 | G175: =F175/(1+'02_Rendimientos'!$B$82) -> 1764705.9 | H175: =E175*G175 -> 1764705.9 | I175: =H175*(1+'02_Rendimientos'!$B$83+'02_Rendimientos'!$B$84) -> 2205882.4 | J175: ='05_Carta_Gantt'!E9 -> 46328 | K175: ='05_Carta_Gantt'!F9 -> 46333 | L175: PPTO fila 11
A176: A.1.1/b) | B176: A | C176: Bodega de Materiales | D176: UNI | E176: 1 | F176: 1200000 | G176: =F176/(1+'02_Rendimientos'!$B$82) -> 1008403.4 | H176: =E176*G176 -> 1008403.4 | I176: =H176*(1+'02_Rendimientos'!$B$83+'02_Rendimientos'!$B$84) -> 1260504.2 | J176: ='05_Carta_Gantt'!E9 -> 46328 | K176: ='05_Carta_Gantt'!F9 -> 46333 | L176: PPTO fila 12
A177: A.1.1/c) | B177: A | C177: Servicios higiénicos tipo químicos | D177: UNI | E177: 2 | F177: 850000 | G177: =F177/(1+'02_Rendimientos'!$B$82) -> 714285.71 | H177: =E177*G177 -> 1428571.4 | I177: =H177*(1+'02_Rendimientos'!$B$83+'02_Rendimientos'!$B$84) -> 1785714.3 | J177: ='05_Carta_Gantt'!E9 -> 46328 | K177: ='05_Carta_Gantt'!F9 -> 46333 | L177: PPTO fila 13
A178: A.1.1/d) | B178: A | C178: Comedor | D178: M2 | E178: 10 | F178: 85000 | G178: =F178/(1+'02_Rendimientos'!$B$82) -> 71428.571 | H178: =E178*G178 -> 714285.71 | I178: =H178*(1+'02_Rendimientos'!$B$83+'02_Rendimientos'!$B$84) -> 892857.14 | J178: ='05_Carta_Gantt'!E9 -> 46328 | K178: ='05_Carta_Gantt'!F9 -> 46333 | L178: PPTO fila 14
A179: A.1.2 | B179: A | C179: CIERRE PROVISORIO | D179: ML | E179: 84 | F179: 14500 | G179: =F179/(1+'02_Rendimientos'!$B$82) -> 12184.874 | H179: =E179*G179 -> 1023529.4 | I179: =H179*(1+'02_Rendimientos'!$B$83+'02_Rendimientos'!$B$84) -> 1279411.8 | J179: ='05_Carta_Gantt'!E9 -> 46328 | K179: ='05_Carta_Gantt'!F9 -> 46333 | L179: PPTO fila 15
A180: A.1.3 | B180: A | C180: LETRERO DE OBRA | D180: UNI | E180: 1 | F180: 390000 | G180: =F180/(1+'02_Rendimientos'!$B$82) -> 327731.09 | H180: =E180*G180 -> 327731.09 | I180: =H180*(1+'02_Rendimientos'!$B$83+'02_Rendimientos'!$B$84) -> 409663.87 | J180: ='05_Carta_Gantt'!E9 -> 46328 | K180: ='05_Carta_Gantt'!F9 -> 46333 | L180: PPTO fila 16
A181: A.2.1 | B181: A | C181: Limpieza y despeje de Terreno | D181: M2 | E181: 444.51 | F181: 2200 | G181: =F181/(1+'02_Rendimientos'!$B$82) -> 1848.7395 | H181: =E181*G181 -> 821783.19 | I181: =H181*(1+'02_Rendimientos'!$B$83+'02_Rendimientos'!$B$84) -> 1027229 | J181: ='05_Carta_Gantt'!E9 -> 46328 | K181: ='05_Carta_Gantt'!F9 -> 46333 | L181: PPTO fila 18
...

Sheet 07_Curvas_S
A1: CURVAS S · PANEL INTEGRADO · ES3 IND. 7 Y 8
A4: PASO 7 · AVANCE FÍSICO Y FINANCIERO
A5: Avance físico ponderado por jornadas base de las 22 actividades (no suma unidades heterogéneas). Avance financiero: costo directo y venta neta distribuidos uniformemente en el intervalo de cada partida.
A6: Resumen semanal y gráficos. El desarrollo diario por partida se presenta debajo: curva física desde la fila 69 y financiera desde la fila 147.
A8: Semana | B8: Desde | C8: Hasta | D8: Físico período | E8: Físico acumulado | F8: CD período | G8: CD acumulado | H8: Venta neta período | I8: Venta neta acum.
A9: 1 | B9: ='02_Rendimientos'!B79+0 -> 46328 | C9: =MIN(B9+6,'05_Carta_Gantt'!$F$30) -> 46334 | D9: =SUMPRODUCT($B$38:$B$59,H38:H59) -> 0.015545137 | E9: =SUM(D$9:D9) -> 0.015545137 | F9: =SUMPRODUCT($C$38:$C$59,H38:H59) -> 7245896 | G9: =SUM(F$9:F9) -> 7245896 | H9: =SUMPRODUCT($D$38:$D$59,H38:H59) -> 9057370 | I9: =SUM(H$9:H9) -> 9057370
A10: 2 | B10: ='02_Rendimientos'!B79+7 -> 46335 | C10: =MIN(B10+6,'05_Carta_Gantt'!$F$30) -> 46341 | D10: =SUMPRODUCT($B$38:$B$59,I38:I59) -> 0.033512893 | E10: =SUM(D$9:D10) -> 0.049058031 | F10: =SUMPRODUCT($C$38:$C$59,I38:I59) -> 771928.56 | G10: =SUM(F$9:F10) -> 8017824.5 | H10: =SUMPRODUCT($D$38:$D$59,I38:I59) -> 964910.7 | I10: =SUM(H$9:H10) -> 10022281
A11: 3 | B11: ='02_Rendimientos'!B79+14 -> 46342 | C11: =MIN(B11+6,'05_Carta_Gantt'!$F$30) -> 46348 | D11: =SUMPRODUCT($B$38:$B$59,J38:J59) -> 0.025639382 | E11: =SUM(D$9:D11) -> 0.074697413 | F11: =SUMPRODUCT($C$38:$C$59,J38:J59) -> 336898.4 | G11: =SUM(F$9:F11) -> 8354722.9 | H11: =SUMPRODUCT($D$38:$D$59,J38:J59) -> 421122.99 | I11: =SUM(H$9:H11) -> 10443404
A12: 4 | B12: ='02_Rendimientos'!B79+21 -> 46349 | C12: =MIN(B12+6,'05_Carta_Gantt'!$F$30) -> 46355 | D12: =SUMPRODUCT($B$38:$B$59,K38:K59) -> 0.024618742 | E12: =SUM(D$9:D12) -> 0.099316155 | F12: =SUMPRODUCT($C$38:$C$59,K38:K59) -> 1273665.6 | G12: =SUM(F$9:F12) -> 9628388.5 | H12: =SUMPRODUCT($D$38:$D$59,K38:K59) -> 1592082 | I12: =SUM(H$9:H12) -> 12035486
A13: 5 | B13: ='02_Rendimientos'!B79+28 -> 46356 | C13: =MIN(B13+6,'05_Carta_Gantt'!$F$30) -> 46362 | D13: =SUMPRODUCT($B$38:$B$59,L38:L59) -> 0.048864958 | E13: =SUM(D$9:D13) -> 0.14818111 | F13: =SUMPRODUCT($C$38:$C$59,L38:L59) -> 1678259.4 | G13: =SUM(F$9:F13) -> 11306648 | H13: =SUMPRODUCT($D$38:$D$59,L38:L59) -> 2097824.2 | I13: =SUM(H$9:H13) -> 14133310
A14: 6 | B14: ='02_Rendimientos'!B79+35 -> 46363 | C14: =MIN(B14+6,'05_Carta_Gantt'!$F$30) -> 46369 | D14: =SUMPRODUCT($B$38:$B$59,M38:M59) -> 0.047147889 | E14: =SUM(D$9:D14) -> 0.195329 | F14: =SUMPRODUCT($C$38:$C$59,M38:M59) -> 2634059.4 | G14: =SUM(F$9:F14) -> 13940707 | H14: =SUMPRODUCT($D$38:$D$59,M38:M59) -> 3292574.2 | I14: =SUM(H$9:H14) -> 17425884
A15: 7 | B15: ='02_Rendimientos'!B79+42 -> 46370 | C15: =MIN(B15+6,'05_Carta_Gantt'!$F$30) -> 46376 | D15: =SUMPRODUCT($B$38:$B$59,N38:N59) -> 0.032481284 | E15: =SUM(D$9:D15) -> 0.22781029 | F15: =SUMPRODUCT($C$38:$C$59,N38:N59) -> 1998323 | G15: =SUM(F$9:F15) -> 15939030 | H15: =SUMPRODUCT($D$38:$D$59,N38:N59) -> 2497903.7 | I15: =SUM(H$9:H15) -> 19923788
A16: 8 | B16: ='02_Rendimientos'!B79+49 -> 46377 | C16: =MIN(B16+6,'05_Carta_Gantt'!$F$30) -> 46383 | D16: =SUMPRODUCT($B$38:$B$59,O38:O59) -> 0.070338662 | E16: =SUM(D$9:D16) -> 0.29814895 | F16: =SUMPRODUCT($C$38:$C$59,O38:O59) -> 8554785 | G16: =SUM(F$9:F16) -> 24493815 | H16: =SUMPRODUCT($D$38:$D$59,O38:O59) -> 10693481 | I16: =SUM(H$9:H16) -> 30617269
A17: 9 | B17: ='02_Rendimientos'!B79+56 -> 46384 | C17: =MIN(B17+6,'05_Carta_Gantt'!$F$30) -> 46390 | D17: =SUMPRODUCT($B$38:$B$59,P38:P59) -> 0.064059801 | E17: =SUM(D$9:D17) -> 0.36220875 | F17: =SUMPRODUCT($C$38:$C$59,P38:P59) -> 7743974.9 | G17: =SUM(F$9:F17) -> 32237790 | H17: =SUMPRODUCT($D$38:$D$59,P38:P59) -> 9679968.6 | I17: =SUM(H$9:H17) -> 40297238
A18: 10 | B18: ='02_Rendimientos'!B79+63 -> 46391 | C18: =MIN(B18+6,'05_Carta_Gantt'!$F$30) -> 46397 | D18: =SUMPRODUCT($B$38:$B$59,Q38:Q59) -> 0.051529251 | E18: =SUM(D$9:D18) -> 0.413738 | F18: =SUMPRODUCT($C$38:$C$59,Q38:Q59) -> 4421111.1 | G18: =SUM(F$9:F18) -> 36658901 | H18: =SUMPRODUCT($D$38:$D$59,Q38:Q59) -> 5526388.9 | I18: =SUM(H$9:H18) -> 45823626
A19: 11 | B19: ='02_Rendimientos'!B79+70 -> 46398 | C19: =MIN(B19+6,'05_Carta_Gantt'!$F$30) -> 46404 | D19: =SUMPRODUCT($B$38:$B$59,R38:R59) -> 0.053256489 | E19: =SUM(D$9:D19) -> 0.46699449 | F19: =SUMPRODUCT($C$38:$C$59,R38:R59) -> 3452914.2 | G19: =SUM(F$9:F19) -> 40111815 | H19: =SUMPRODUCT($D$38:$D$59,R38:R59) -> 4316142.8 | I19: =SUM(H$9:H19) -> 50139769
A20: 12 | B20: ='02_Rendimientos'!B79+77 -> 46405 | C20: =MIN(B20+6,'05_Carta_Gantt'!$F$30) -> 46411 | D20: =SUMPRODUCT($B$38:$B$59,S38:S59) -> 0.058918479 | E20: =SUM(D$9:D20) -> 0.52591297 | F20: =SUMPRODUCT($C$38:$C$59,S38:S59) -> 5755007.7 | G20: =SUM(F$9:F20) -> 45866823 | H20: =SUMPRODUCT($D$38:$D$59,S38:S59) -> 7193759.6 | I20: =SUM(H$9:H20) -> 57333529
A21: 13 | B21: ='02_Rendimientos'!B79+84 -> 46412 | C21: =MIN(B21+6,'05_Carta_Gantt'!$F$30) -> 46418 | D21: =SUMPRODUCT($B$38:$B$59,T38:T59) -> 0.059682224 | E21: =SUM(D$9:D21) -> 0.58559519 | F21: =SUMPRODUCT($C$38:$C$59,T38:T59) -> 8345204.8 | G21: =SUM(F$9:F21) -> 54212028 | H21: =SUMPRODUCT($D$38:$D$59,T38:T59) -> 10431506 | I21: =SUM(H$9:H21) -> 67765035
A22: 14 | B22: ='02_Rendimientos'!B79+91 -> 46419 | C22: =MIN(B22+6,'05_Carta_Gantt'!$F$30) -> 46425 | D22: =SUMPRODUCT($B$38:$B$59,U38:U59) -> 0.067861266 | E22: =SUM(D$9:D22) -> 0.65345646 | F22: =SUMPRODUCT($C$38:$C$59,U38:U59) -> 6711535.1 | G22: =SUM(F$9:F22) -> 60923563 | H22: =SUMPRODUCT($D$38:$D$59,U38:U59) -> 8389418.9 | I22: =SUM(H$9:H22) -> 76154454
A23: 15 | B23: ='02_Rendimientos'!B79+98 -> 46426 | C23: =MIN(B23+6,'05_Carta_Gantt'!$F$30) -> 46432 | D23: =SUMPRODUCT($B$38:$B$59,V38:V59) -> 0.064887069 | E23: =SUM(D$9:D23) -> 0.71834353 | F23: =SUMPRODUCT($C$38:$C$59,V38:V59) -> 1357500 | G23: =SUM(F$9:F23) -> 62281063 | H23: =SUMPRODUCT($D$38:$D$59,V38:V59) -> 1696875 | I23: =SUM(H$9:H23) -> 77851329
A24: 16 | B24: ='02_Rendimientos'!B79+105 -> 46433 | C24: =MIN(B24+6,'05_Carta_Gantt'!$F$30) -> 46439 | D24: =SUMPRODUCT($B$38:$B$59,W38:W59) -> 0.055405989 | E24: =SUM(D$9:D24) -> 0.77374952 | F24: =SUMPRODUCT($C$38:$C$59,W38:W59) -> 1722169.4 | G24: =SUM(F$9:F24) -> 64003232 | H24: =SUMPRODUCT($D$38:$D$59,W38:W59) -> 2152711.7 | I24: =SUM(H$9:H24) -> 80004041
